Workbook
Name upahbahan: '[1]Upah Bahan'!$F$9:$H$2830

Sheet BOQ STRUKTUR
B7: No. | C7: PEKERJAAN | D7: VOLUME | E7: UNIT | F7: UNIT PRICE | G7: HARGA
B8: 1 | C8: 2 | D8: 3 | E8: 4 | F8: 5 | G8: 6 | J8: L | K8: P | L8: D | M8: V | N8: jml | O8: Vol | Q8: Luas
I9: Basement | J9: 20.3 | K9: 54.45 | L9: 2.5 | M9: =L9*K9*J9 -> 2763.3375 | Q9: =J9*K9 -> 1105.335
B10: I | C10: Pekerjaan Tanah | AG10: CATATAN:
B11: A | C11: Galian | I11: Ramp | J11: 2.9 | K11: 5.3 | L11: 2.5 | M11: =L11*K11*J11 -> 38.425 | Q11: =J11*K11 -> 15.37 | AG11: JANGAN MEN DELATE CELL
B12: 1 | C12: Plat basement | D12: =M9 -> 2763.3375 | E12: m3 | F12: =AHSP!$I$3 -> 52800 | G12: =D12*F12 -> 145904220 | J12: 2.8 | K12: 19.3 | L12: 1.25 | M12: =L12*K12*J12 -> 67.55 | Q12: =J12*K12 -> 54.04 | AG12: ADA RUMUS DAN DATA PADA CELL YG DI HIDE
B13: 2 | C13: Sloop | D13: =O22 -> 165.197 | E13: m3 | F13: =AHSP!$I$3 -> 52800 | G13: =D13*F13 -> 8722401.6 | M13: =SUM(M11:M12) -> 105.975
B14: 3 | C14: Poor | D14: =N28 -> 110.2 | E14: m3 | F14: =AHSP!$I$3 -> 52800 | G14: =D14*F14 -> 5818560 | I14: Ground tnk | J14: 3.5 | K14: 4 | L14: 3 | M14: =L14*K14*J14 -> 42 | N14: 2 | O14: =M14*N14 -> 84 | Q14: =J14*K14 -> 14 | R14: Tinggi
B15: 4 | C15: Galian ramp | D15: =M13 -> 105.975 | E15: m3 | F15: =AHSP!$I$3 -> 52800 | G15: =D15*F15 -> 5595480 | I15: S45/70 | J15: 0.65 | K15: 7.8 | L15: 0.5 | M15: =L15*K15*J15 -> 2.535 | N15: 9 | O15: =N15*M15*L15 -> 11.4075 | Q15: =SUM(Q9:Q14) -> 1188.745 | R15: 0.6 | S15: =R15*K15*N15*2 -> 84.24
B16: 5 | C16: Galian ground tank tank | D16: =O14 -> 84 | E16: m3 | F16: =AHSP!$I$3 -> 52800 | G16: =D16*F16 -> 4435200 | I16: S40/60 | J16: 0.6 | K16: 5.9 | L16: 0.4 | M16: =L16*K16*J16 -> 1.416 | N16: 18 | O16: =M16*N16 -> 25.488 | R16: 0.4 | S16: =R16*K16*N16*2 -> 84.96
J17: 0.6 | K17: 53.75 | L17: 0.4 | M17: =L17*K17*J17 -> 12.9 | N17: 2 | O17: =M17*N17 -> 25.8 | R17: 0.4 | S17: =R17*K17*N17*2 -> 86
B18: B | C18: Pemadatan tanah galian | D18: =Q15 -> 1188.745 | E18: m2 | F18: =AHSP!I18 -> 24500 | G18: =D18*F18 -> 29124252 | I18: S35/50 | J18: 0.55 | K18: =2*6.8+2*5.15 -> 23.9 | L18: 0.3 | M18: =L18*K18*J18 -> 3.9435 | N18: 1 | O18: =M18*N18 -> 3.9435 | R18: 0.4 | S18: =R18*K18*N18*2 -> 19.12
J19: 0.55 | K19: =4*9+19.6*2 -> 75.2 | L19: 0.3 | M19: =L19*K19*J19 -> 12.408 | N19: 1 | O19: =M19*N19 -> 12.408 | R19: 0.4 | S19: =R19*K19*N19*2 -> 60.16
B20: C | C20: Pembuangan tanah keluar | D20: =SUM(D12:D16) -> 3228.7095 | E20: m3 | F20: =AHSP!I32 -> 29900 | G20: =D20*F20 -> 96538414
F21: Sub Total I | G21: =SUM(G12:G20) -> 2.9613853e+08 | I21: S30/45 | J21: 0.5 | K21: =2*8.6 -> 17.2 | L21: 0.25 | M21: =L21*K21*J21 -> 2.15 | N21: 1 | O21: =M21*N21 -> 2.15 | R21: 0.4 | S21: =R21*K21*N21*2 -> 13.76
O22: =SUM(O14:O21) -> 165.197 | S22: =SUM(S15:S21) -> 348.24
B23: II | C23: Pekerjaan Pondasi tiang pancang | D23: 220 | E23: buah | G23: =D23*F23 -> 0 | J23: L | K23: P | L23: D | M23: Jml | N23: Vol | P23: Jml | Q23: Vol
F24: Sub Total II | G24: =SUM(G23) -> 0 | I24: P1 | J24: 1 | K24: 1 | L24: 0.5 | M24: 26 | N24: =M24*L24*K24*J24 -> 13 | P24: 1 | Q24: =P24*M24 -> 26 | R24: 0.6 | S24: =2*(J24+K24)*M24*R24 -> 62.4
I25: P2 | J25: 1.2 | K25: 2 | L25: 0.5 | M25: 11 | N25: =M25*L25*K25*J25 -> 13.2 | P25: 2 | Q25: =P25*M25 -> 22 | R25: 0.6 | S25: =2*(J25+K25)*M25*R25 -> 42.24
B26: III | C26: Pekerjaan Lantai Basement | I26: P3 | J26: 2 | K26: 2 | L26: 0.5 | M26: 20 | N26: =M26*L26*K26*J26 -> 40 | P26: 3 | Q26: =P26*M26 -> 60 | R26: 0.6 | S26: =2*(J26+K26)*M26*R26 -> 96
B27: A | C27: Pasang bekisting batako | I27: P4 | J27: 2 | K27: 2 | L27: 0.5 | M27: 22 | N27: =M27*L27*K27*J27 -> 44 | P27: 5 | Q27: =P27*M27 -> 110 | R27: 0.6 | S27: =2*(J27+K27)*M27*R27 -> 105.6
B28: 1 | C28: Sloop | D28: =S22 -> 348.24 | E28: m2 | F28: =AHSP!$H$47 -> 272100 | G28: =D28*F28 -> 94756104 | N28: =SUM(N24:N27) -> 110.2 | Q28: =SUM(Q24:Q27) -> 218 | S28: =SUM(S24:S27) -> 306.24
B29: 2 | C29: Poor | D29: =S28 -> 306.24 | E29: m2 | F29: =AHSP!$H$47 -> 272100 | G29: =D29*F29 -> 83327904 | J29: Pnj | K29: D19 | L29: D16 | M29: d8 | N29: brt19 | O29: brt16 | P29: brt8 | U29: Berat besi
B30: B | C30: Lantai kerja | D30: =D18 -> 1188.745 | E30: m2 | F30: =AHSP!$H$47 -> 272100 | G30: =D30*F30 -> 3.2345751e+08 | I30: S45/70 | J30: =K15*N15 -> 70.2 | K30: 9 | L30: 5 | M30: =1.8/0.15 -> 12 | N30: 2.23 | O30: 1.58 | P30: 0.395 | Q30: =1.1*J30*(K30*N30+L30*O30+M30*P30) -> 2525.8662 | T30: d8 | U30: d10 | V30: D13 | W30: D16 | X30: D19 | Y30: D22
B31: C | C31: Pekerjaan besi beton | I31: S40/60 | J31: =K16*N16 -> 106.2 | K31: 8.5 | L31: 2 | M31: =1.56/0.15 -> 10.4 | N31: 2.23 | O31: 1.58 | P31: 0.395 | Q31: =1.1*J31*(K31*N31+L31*O31+M31*P31) -> 3063.3709 | T31: 0.395 | U31: 0.62 | V31: 1.04 | W31: 1.58 | X31: 2.23 | Y31: 2.98
B32: 1 | C32: Sloop 45/70 | D32: =Q30 -> 2525.8662 | E32: kg | F32: =AHSP!$H$67 -> 19300 | G32: =D32*F32 -> 48749218 | I32: S2*40/60 | J32: =2*53.75 -> 107.5 | L32: 13 | M32: =M31 -> 10.4 | N32: 2.23 | O32: 1.58 | P32: 0.395 | Q32: =1.1*J32*(K32*N32+L32*O32+M32*P32) -> 2914.626
B33: 2 | C33: Sloop 40/60 | D33: =Q31 -> 3063.3709 | E33: kg | F33: =AHSP!$H$67 -> 19300 | G33: =D33*F33 -> 59123058 | I33: S35/50 | J33: =K18+K19 -> 99.1 | L33: 10 | M33: =1.2/0.15 -> 8 | N33: 2.23 | O33: 1.58 | P33: 0.395 | Q33: =1.1*J33*(K33*N33+L33*O33+M33*P33) -> 2066.8296
B34: 3 | C34: Sloop 40/60* | D34: =Q32 -> 2914.626 | E34: kg | F34: =AHSP!$H$67 -> 19300 | G34: =D34*F34 -> 56252282 | I34: S30/45 | J34: =K21 -> 17.2 | L34: 8 | M34: 8 | N34: 2.23 | O34: 1.58 | P34: 0.395 | Q34: =1.1*J34*(K34*N34+L34*O34+M34*P34) -> 298.936
B35: 4 | C35: Sloop 35/50 | D35: =Q33 -> 2066.8296 | E35: kg | F35: =AHSP!$H$67 -> 19300 | G35: =D35*F35 -> 39889811 | N35: D19 | O35: D16 | P35: brt19 | Q35: brt16 | R35: berat | S35: Jml | T35: Vol
B36: 5 | C36: Sloop 30/45 | D36: =Q34 -> 298.936 | E36: kg | F36: =AHSP!$H$67 -> 19300 | G36: =D36*F36 -> 5769464.8 | I36: P1 | J36: 0.75 | K36: 0.65 | L36: =K36+J36 -> 1.4 | M36: 6 | N36: =2*M36*L36 -> 16.8 | O36: =N36+K36*4 -> 19.4 | P36: 2.23 | Q36: 1.58 | R36: =N36*P36+O36*Q36 -> 68.116 | S36: 26 | T36: =S36*R36 -> 1771.016
B37: 6 | C37: Poor P1 | D37: =T36 -> 1771.016 | E37: kg | F37: =AHSP!$H$67 -> 19300 | G37: =D37*F37 -> 34180609 | I37: P2 | J37: 0.75 | K37: 1.65 | L37: =K37+J37 -> 2.4 | M37: 9 | N37: =2*M37*L37 -> 43.2 | O37: =N37+2*(1.65+0.85) -> 48.2 | P37: 2.23 | Q37: 1.58 | R37: =N37*P37+O37*Q37 -> 172.492 | S37: 11 | T37: =S37*R37 -> 1897.412
B38: 7 | C38: Poor P2 | D38: =T37 -> 1897.412 | E38: kg | F38: =AHSP!$H$67 -> 19300 | G38: =D38*F38 -> 36620052 | J38: 0.75 | K38: 1.15 | L38: =K38+J38 -> 1.9 | M38: 10 | N38: =2*M38*L38 -> 38
B39: 8 | C39: Poor P3 | D39: =T40 -> 5298.72 | E39: kg | F39: =AHSP!$H$67 -> 19300 | G39: =D39*F39 -> 1.022653e+08 | J39: 0.75 | K39: 1.65 | L39: =K39+J39 -> 2.4 | M39: 6 | N39: =2*M39*L39 -> 28.8
B40: 9 | C40: Poor P4 | D40: =T41 -> 6666.792 | E40: kg | F40: =AHSP!$H$67 -> 19300 | G40: =D40*F40 -> 1.2866909e+08 | I40: P3 | N40: =SUM(N38:N39) -> 66.8 | O40: =N40+4*K39 -> 73.4 | P40: 2.23 | Q40: 1.58 | R40: =N40*P40+O40*Q40 -> 264.936 | S40: 20 | T40: =S40*R40 -> 5298.72
B41: 10 | C41: Pelat basement Wiremesh M10 | D41: =Q9*2 -> 2210.67 | E41: m2 | F41: =AHSP!$H$152 -> 13800 | G41: =D41*F41 -> 30507246 | I41: P4 | J41: 0.75 | K41: 1.65 | L41: =K41+J41 -> 2.4 | M41: 16 | N41: =2*M41*L41 -> 76.8 | O41: =N41+4*K41 -> 83.4 | P41: 2.23 | Q41: 1.58 | R41: =N41*P41+O41*Q41 -> 303.036 | S41: 22 | T41: =S41*R41 -> 6666.792
B42: 11 | C42: Besi ulir D13 -300 | D42: =N43 -> 3831.828 | E42: kg | F42: =AHSP!$H$67 -> 19300 | G42: =D42*F42 -> 73954280 | J42: L | K42: P | L42: D13 | M42: brt13 | N42: Vol
B43: D | C43: Beton F'c 25 Mpa. | I43: Basement | J43: 20.3 | K43: 54.45 | L43: =K43/0.3*J43/2*2 -> 3684.45 | M43: 1.04 | N43: =M43*L43 -> 3831.828
B44: 1 | C44: Sloop 45/70 | D44: =O45 -> 31.941 | E44: m3 | F44: =AHSP!$H$107 -> 1382600 | G44: =D44*F44 -> 44161627 | J44: L | K44: P | L44: T | M44: Jml | O44: Vol | R44: L | S44: P | T44: D | U44: Jml | V44: Vol
B45: 2 | C45: Sloop 40/60 | D45: =N46 -> 38.232 | E45: m3 | F45: =AHSP!$H$107 -> 1382600 | G45: =D45*F45 -> 52859563 | I45: S45/70 | J45: 0.65 | K45: 7.8 | L45: 0.7 | M45: 9 | O45: =J45*K45*L45*M45 -> 31.941 | Q45: P1 | R45: 0.8 | S45: 0.8 | T45: 0.65 | U45: 26 | V45: =U45*T45*S45*R45 -> 10.816 | Y45: Sk | Z45: kait | AA45: kait
B46: 3 | C46: Sloop 40/60* | D46: =N47 -> 38.7 | E46: m3 | F46: =AHSP!$H$107 -> 1382600 | G46: =D46*F46 -> 53506620 | I46: S40/60 | J46: 0.6 | K46: 5.9 | L46: 0.6 | M46: 18 | N46: =M46*L46*K46*J46 -> 38.232 | Q46: P2 | R46: 1 | S46: 1.8 | T46: 0.65 | U46: 11 | V46: =U46*T46*S46*R46 -> 12.87 | Y46: d10 | Z46: d10 | AA46: d8
...

Sheet AHSP
B3: 1 | C3: Penggalian 1 m3 tanah biasa sedalam 0 s.d. 1 m untuk volume > 2.000 m3 secara Manual | I3: =ROUNDDOWN(G15,-2) -> 52800
B4: No | C4: Uraian | D4: Sat. | E4: Koefisien | F4: Harga Satuan (Rp) | G4: Jumlah Harga (Rp)
B5: A | C5: TENAGA KERJA
B6: 1 | C6: Pekerja | D6: OH | E6: 0.4 | F6: =VLOOKUP(C6,upahbahan,3,FALSE) -> 100000 | G6: =E6*F6 -> 40000
B7: 2 | C7: Mandor | D7: OH | E7: 0.04 | F7: =VLOOKUP(C7,upahbahan,3,FALSE) -> 200000 | G7: =E7*F7 -> 8000
B8: JUMLAH HARGA TENAGA KERJA | G8: =SUM(G6:G7) -> 48000
B9: B | C9: BAHAN
B10: JUMLAH HARGA BAHAN | G10: 0
B11: C | C11: PERALATAN
B12: JUMLAH HARGA ALAT | G12: 0
B13: D | C13: Jumlah (A+B+C) | G13: =G8+G10+G12 -> 48000
B14: E | C14: Biaya Umum dan Keuntungan 10%-15% x D | F14: 0.1 | G14: =G13*F14 -> 4800
B15: F | C15: Harga Satuan Pekerjaan (D+E) | G15: =SUM(G13:G14) -> 52800
B18: 2 | C18: 1 m3 Pemadatan tanah setebal 10 cm menggunakan mesin Stemper kuda semi mekanis | I18: =ROUNDDOWN(G29,-2) -> 24500
B19: No | C19: Uraian | D19: Sat. | E19: Koefisien | F19: Harga Satuan (Rp) | G19: Jumlah Harga (Rp)
B20: A | C20: TENAGA KERJA
B21: JUMLAH HARGA TENAGA KERJA | G21: =SUM(G20) -> 0
B22: B | C22: BAHAN
B23: JUMLAH HARGA BAHAN | G23: =SUM(G22) -> 0
B24: C | C24: PERALATAN
B25: 1 | C25: Stamper Kuda | D25: hari | E25: 0.077 | F25: =VLOOKUP(C25,upahbahan,3,FALSE) -> 290000 | G25: =E25*F25 -> 22330
B26: JUMLAH HARGA ALAT | G26: =SUM(G25) -> 22330
B27: D | C27: Jumlah (A+B+C) | G27: =G21+G23+G26 -> 22330
B28: E | C28: Biaya Umum dan Keuntungan 10% - 15% x D | F28: 0.1 | G28: =G27*F28 -> 2233
B29: F | C29: Harga Satuan Pekerjaan (D+E) | G29: =SUM(G27:G28) -> 24563
B32: 3 | C32: Mengangkut 1 m3 tanah lepas, jarak angkut > 20 m s.d 30 m | I32: =ROUNDDOWN(G44,-2) -> 29900
B33: No | C33: Uraian | D33: Sat. | E33: Koefisien | F33: Harga Satuan (Rp) | G33: Jumlah Harga (Rp)
B34: A | C34: TENAGA KERJA
B35: 1 | C35: Pekerja | D35: OH | E35: 0.2363 | F35: =VLOOKUP(C35,upahbahan,3,FALSE) -> 100000 | G35: =F35*E35 -> 23630
B36: 2 | C36: Mandor | D36: OH | E36: 0.018 | F36: =VLOOKUP(C36,upahbahan,3,FALSE) -> 200000 | G36: =F36*E36 -> 3600
B37: JUMLAH HARGA TENAGA KERJA | G37: =SUM(G35:G36) -> 27230
B38: B | C38: BAHAN
B39: JUMLAH HARGA BAHAN | G39: =SUM(G38) -> 0
B40: C | C40: PERALATAN
B41: JUMLAH HARGA ALAT | G41: =SUM(G40) -> 0
B42: D | C42: Jumlah (A+B+C) | G42: =G37+G39+G41 -> 27230
B43: E | C43: Biaya Umum dan Keuntungan 10% - 15% x D | F43: 0.1 | G43: =G42*F43 -> 2723
B44: F | C44: Harga Satuan Pekerjaan (D+E) | G44: =SUM(G42:G43) -> 29953
B47: 4 | C47: Pemasangan 1 m2 bekisting untuk sloof (3 kali pakai) | H47: =ROUNDDOWN(G64,-2) -> 272100
B48: No | C48: Uraian | D48: Sat. | E48: Koefisien | F48: Harga Satuan (Rp) | G48: Jumlah Harga (Rp)
...
