Workbook
Name TENAGA: #REF!
Name upahbahan: '[1]Upah Bahan'!$F$9:$H$2830

Sheet ANALISA VOLUME
B2: ANALISA VOLUME
B3: RSU. SARI DHARMA
B7: NO | C7: ITEM PEKERJAAN | D7: SAT. | E7: VOLUME | L7: VOLUME
E8: BASEMENT | F8: LT.1 | G8: LT.2 | H8: LT.3 | I8: LT.4 | J8: ROOFTOP | L8: TOTAL
B10: I | C10: PEKERJAAN ARSITEKTUR
B12: 1 | C12: PAS. DINDING BATA :
C13: 1. ARAH HORISONTAL | D13: M | E13: =(53.75+(2+1.2+1.8)+(5.8+1.7+2+3.2+4)+(8.1+2+5.2)+(1+16.75)+(5.7+3.3+4)+(9+4)+(9+6+2.8+9)+(8.5+2.3+3.65+2.3)+(2+2.3+3.65+3.4)+53.75) -> 243.15 | F13: =(53.75+(1.75+2.4+1.35+2)+(7.55+3+3.4+1.3+4.7+1.6+3.15)+(3+1.45+2+4.25+9)+(3.55+4+12.25+2.6)+(6.75+4)+(8+4+11.4)+(4+4+3.25)+(6.175+5.75+1.7+4)+(9+15.25+3.6+5)+(6.2+4+9.35+5.75)+(3.85+2+1.2+1.75+2.6)+53.75) -> 314.375 | G13: =(56.25+(3.5+1.8+5.1+4.87+1.2)+(3+1.8+1.6+4.1+4+1.6+6+5.38)+(56.25-(6.95+1+2))+(4+6.8+18.32+4)+(6.8+13.14+4.1+1.82)+(7+14+17.8)+(3.1+4.7+3+2.3+13.55)+(23.28-4)+56.25) -> 346.46 | H13: =(56.25+(6.75+2.5+2.2+4.5+4.5+1.65+1+3+4.05+1.95+1.95+1.95)+(6.75+6.9+30.15+1.65)+(4.5+4.5+13.5)+(16+13.5)+(27+18.5)+(2+2+2+2+15.66)+56.25) -> 315.11 | I13: =(56.25+(4.6+2.85+(1.65*6))+(2.5+1.65+3.1+4.65+(4.65*5))+(4.95+4.65+(6*5))+(6.5+8.75+2.5)+(9.7+13)+((6*4)+7.58+3.42)+(39.8+8.95)+56.25) -> 328.8 | J13: =(4.5+1.65+(9.15+2.45+1.25+6.7+9.7+2+5+9.7)+(10.3+(1.5*4)+10.3+1.6+10.3)+(20.7+6+2.45+20.7)) -> 140.45
C14: 2. ARAH VERTIKAL | D14: M | E14: =(19.6+19.6+(1.8+3.1+1.5)+(5.9+5.9+1.8)+(5.9+2.8+5.9)+(2+2)+(5.9+4+5.9+5.9)+5.9+(5.9+5.9+5.9+3+3.6+5.9)+2.6+(7.8+3.5+3+5.9)+(3.5+3.5+2.4)+19.6) -> 187.4 | F14: =(19.6+(2.3+7.8+1.9)+(9+4)+(9+5.9)+(3.98+3.98+1.45+8)+(2.45+3.8)+(2.45+2.45+8.05)+(3+3+8.05+4.19)+(5.9+5.9)+(1.6+1.6+5.9+2.3)+(5.9+2+5.9+5.9)+(5.9+7.8)+2.8+(3.6+4+5.9+2)+(5.9+2+2)+(4+7+2.88)+(1.86+10.92)) -> 225.81 | G14: =(19.6+(19.6-(1.9+1.5))+(5.6+3)+(19.6-2.7)+(6+9+(2.5*3))+((5.9*2)+(4.5*2))+(5.9+5.9+2)+(5.9+4.9+4)+((5.9*2)+2+(4.9*2))+(5.9+7.8+(1.8*4))+17.6+19.6+19.6) -> 234.5 | H14: =(19.61+(2.45+2.45+2.45+8.35)+(2.5+5.35+5.9)+(5.9+3+2.15+2.15)+((2.45*4)+(2.15*3))+(5.9+3.6)+(2.45+2.45+5.9)+(5.9+(2.45*4))+(2.75+3.5+2.5+5.9+3.5)+(3.5+5.3)+((4+5.3+5.9)*2)+(2+5.9)+(4.9+5.3+5.9)+((0.4*3)+3.8+2.25+2.25)+19.61) -> 224.97 | I14: =(19.6+(2.3+2.4+1.8+2.4+0.6+3)+(5.9+3.7+5.9+4)+(3.7+4)+(3.7+4)+2.23+(2.3+5.9+2.3+2.14+2.14)+(5.9+4+5.9)+(2.3+5.9)+(5.9+5.9+2.3)+(3.5+2.5+2.3)+(3.5+5.9)+(5.9+5.4+2.3)+(1.89+3+5.9)+(5.9+3+2.3)+(0.6+0.6+1+2.4+5.9)+19.6) -> 205.5 | J14: =(16.3+3.15+4.15+2+2+8+1.6+17.8)+(3.4+3.4)+(7.35+3+3+3+7.35)+(16.45+2.5+1.6+2.5+16.45) -> 125
C15: 3. TINGGI DINDING | D15: M | E15: 3.2 | F15: 3.7 | G15: 4.7 | H15: 3.3 | I15: 3.3 | J15: 2.8
C16: VOL. TOTAL | D16: M2 | E16: =(E13+E14)*E15 -> 1377.76 | F16: =(F13+F14)*F15 -> 1998.6845 | G16: =(G13+G14)*G15 -> 2730.512 | H16: =(H13+H14)*H15 -> 1782.264 | I16: =(I13+I14)*I15 -> 1763.19 | J16: =(J13+J14)*J15 -> 743.26 | L16: =SUM(E16:J16) -> 10395.671
C17: VOL. PASANGAN - LUBANG PINTU JEND | D17: M2
B19: 2 | C19: PEKERJAAN PINTU JENDELA
C20: PINTU P1 | D20: UNIT | E20: 5 | F20: 19 | G20: 23 | H20: 18 | I20: 20 | J20: 4 | L20: =SUM(E20:J20) -> 89 | M20: M2 | N20: =E20*'ANALISA PINTU JENDELA'!$C$6 -> 11.4 | O20: =F20*'ANALISA PINTU JENDELA'!$C$6 -> 43.32 | P20: =G20*'ANALISA PINTU JENDELA'!$C$6 -> 52.44 | Q20: =H20*'ANALISA PINTU JENDELA'!$C$6 -> 41.04 | R20: =I20*'ANALISA PINTU JENDELA'!$C$6 -> 45.6 | S20: =J20*'ANALISA PINTU JENDELA'!$C$6 -> 9.12
C21: PINTU P1KM | D21: UNIT | E21: 5 | L21: =SUM(E21:J21) -> 5 | M21: M2 | N21: =E21*'ANALISA PINTU JENDELA'!$C$6 -> 11.4 | O21: =F21*'ANALISA PINTU JENDELA'!$C$6 -> 0 | P21: =G21*'ANALISA PINTU JENDELA'!$C$6 -> 0 | Q21: =H21*'ANALISA PINTU JENDELA'!$C$6 -> 0 | R21: =I21*'ANALISA PINTU JENDELA'!$C$6 -> 0 | S21: =J21*'ANALISA PINTU JENDELA'!$C$6 -> 0
C22: PINTU P2 | D22: UNIT | E22: 13 | F22: =26+3 -> 29 | G22: 21 | H22: 14 | I22: 8 | J22: 6 | L22: =SUM(E22:J22) -> 91 | M22: M2 | N22: =E22*'ANALISA PINTU JENDELA'!$C$19 -> 31.2 | O22: =F22*'ANALISA PINTU JENDELA'!$C$19 -> 69.6 | P22: =G22*'ANALISA PINTU JENDELA'!$C$19 -> 50.4 | Q22: =H22*'ANALISA PINTU JENDELA'!$C$19 -> 33.6 | R22: =I22*'ANALISA PINTU JENDELA'!$C$19 -> 19.2 | S22: =J22*'ANALISA PINTU JENDELA'!$C$19 -> 14.4
C23: PINTU P3 | D23: UNIT | E23: 4 | F23: 9 | G23: 15 | H23: 13 | I23: 14 | J23: 0 | L23: =SUM(E23:J23) -> 55 | M23: M2 | N23: =E23*'ANALISA PINTU JENDELA'!$C$32 -> 12.48 | O23: =F23*'ANALISA PINTU JENDELA'!$C$32 -> 28.08 | P23: =G23*'ANALISA PINTU JENDELA'!$C$32 -> 46.8 | Q23: =H23*'ANALISA PINTU JENDELA'!$C$32 -> 40.56 | R23: =I23*'ANALISA PINTU JENDELA'!$C$32 -> 43.68 | S23: =J23*'ANALISA PINTU JENDELA'!$C$32 -> 0
C24: PINTU P4 | D24: UNIT | E24: 0 | F24: 1 | G24: 0 | H24: 1 | I24: 0 | J24: 4 | L24: =SUM(E24:J24) -> 6 | M24: M2 | N24: =E24*'ANALISA PINTU JENDELA'!$C$59 -> 0 | O24: =F24*'ANALISA PINTU JENDELA'!$C$59 -> 4.08 | P24: =G24*'ANALISA PINTU JENDELA'!$C$59 -> 0 | Q24: =H24*'ANALISA PINTU JENDELA'!$C$59 -> 4.08 | R24: =I24*'ANALISA PINTU JENDELA'!$C$59 -> 0 | S24: =J24*'ANALISA PINTU JENDELA'!$C$59 -> 16.32
C25: PINTU P5 | D25: UNIT | E25: 0 | F25: 0 | G25: 5 | H25: 0 | I25: 0 | J25: 0 | L25: =SUM(E25:J25) -> 5 | M25: M2 | N25: =E25*'ANALISA PINTU JENDELA'!$C$70 -> 0 | O25: =F25*'ANALISA PINTU JENDELA'!$C$70 -> 0 | P25: =G25*'ANALISA PINTU JENDELA'!$C$70 -> 19.2 | Q25: =H25*'ANALISA PINTU JENDELA'!$C$70 -> 0 | R25: =I25*'ANALISA PINTU JENDELA'!$C$70 -> 0 | S25: =J25*'ANALISA PINTU JENDELA'!$C$70 -> 0
C26: PINTU P6 | D26: UNIT | E26: 0 | F26: 0 | G26: 1 | H26: 0 | I26: 0 | J26: 0 | L26: =SUM(E26:J26) -> 1 | M26: M2 | N26: =E26*'ANALISA PINTU JENDELA'!$C$97 -> 0 | O26: =F26*'ANALISA PINTU JENDELA'!$C$97 -> 0 | P26: =G26*'ANALISA PINTU JENDELA'!$C$97 -> 2.28 | Q26: =H26*'ANALISA PINTU JENDELA'!$C$97 -> 0 | R26: =I26*'ANALISA PINTU JENDELA'!$C$97 -> 0 | S26: =J26*'ANALISA PINTU JENDELA'!$C$97 -> 0
C27: PINTU P7 | D27: UNIT | E27: 2 | F27: 0 | G27: 0 | H27: 0 | I27: 0 | J27: 0 | L27: =SUM(E27:J27) -> 2 | M27: M2 | N27: =E27*'ANALISA PINTU JENDELA'!$C$110 -> 4.8 | O27: =F27*'ANALISA PINTU JENDELA'!$C$110 -> 0 | P27: =G27*'ANALISA PINTU JENDELA'!$C$110 -> 0 | Q27: =H27*'ANALISA PINTU JENDELA'!$C$110 -> 0 | R27: =I27*'ANALISA PINTU JENDELA'!$C$110 -> 0 | S27: =J27*'ANALISA PINTU JENDELA'!$C$110 -> 0
C28: PINTU PJ1 | D28: UNIT | E28: 0 | F28: 1 | G28: 0 | H28: 0 | I28: 0 | J28: 0 | L28: =SUM(E28:J28) -> 1 | M28: M2 | N28: =E28*'ANALISA PINTU JENDELA'!$K$6 -> 0 | O28: =F28*'ANALISA PINTU JENDELA'!$K$6 -> 8.568 | P28: =G28*'ANALISA PINTU JENDELA'!$K$6 -> 0 | Q28: =H28*'ANALISA PINTU JENDELA'!$K$6 -> 0 | R28: =I28*'ANALISA PINTU JENDELA'!$K$6 -> 0 | S28: =J28*'ANALISA PINTU JENDELA'!$K$6 -> 0
L29: =SUM(E29:J29) -> 0
C30: JENDELA J1 | D30: UNIT | E30: 0 | F30: 13 | G30: 8 | H30: 3 | I30: 9 | J30: 0 | L30: =SUM(E30:J30) -> 33 | M30: M2 | N30: =E30*'ANALISA PINTU JENDELA'!$K$19 -> 0 | O30: =F30*'ANALISA PINTU JENDELA'!$K$19 -> 23.92 | P30: =G30*'ANALISA PINTU JENDELA'!$K$19 -> 14.72 | Q30: =H30*'ANALISA PINTU JENDELA'!$K$19 -> 5.52 | R30: =I30*'ANALISA PINTU JENDELA'!$K$19 -> 16.56 | S30: =J30*'ANALISA PINTU JENDELA'!$K$19 -> 0
C31: JENDELA J1A | D31: UNIT | E31: 12 | J31: 0 | L31: =SUM(E31:J31) -> 12 | M31: M2 | N31: =E31*'ANALISA PINTU JENDELA'!$K$32 -> 16.56 | O31: =F31*'ANALISA PINTU JENDELA'!$K$32 -> 0 | P31: =G31*'ANALISA PINTU JENDELA'!$K$32 -> 0 | Q31: =H31*'ANALISA PINTU JENDELA'!$K$32 -> 0 | R31: =I31*'ANALISA PINTU JENDELA'!$K$32 -> 0 | S31: =J31*'ANALISA PINTU JENDELA'!$K$32 -> 0
C32: JENDELA J2 | D32: UNIT | E32: 0 | F32: 2 | G32: 2 | H32: 12 | I32: 12 | J32: 0 | L32: =SUM(E32:J32) -> 28 | M32: M2 | N32: =E32*'ANALISA PINTU JENDELA'!$K$45 -> 0 | O32: =F32*'ANALISA PINTU JENDELA'!$K$45 -> 6.88 | P32: =G32*'ANALISA PINTU JENDELA'!$K$45 -> 6.88 | Q32: =H32*'ANALISA PINTU JENDELA'!$K$45 -> 41.28 | R32: =I32*'ANALISA PINTU JENDELA'!$K$45 -> 41.28 | S32: =J32*'ANALISA PINTU JENDELA'!$K$45 -> 0
C33: JENDELA J2A | D33: UNIT | E33: 1 | J33: 0 | L33: =SUM(E33:J33) -> 1 | M33: M2 | N33: =E33*'ANALISA PINTU JENDELA'!K59 -> 2.58
C34: JENDELA J3 | D34: UNIT | E34: 0 | F34: 2 | G34: 4 | H34: 2 | I34: 2 | J34: 0 | L34: =SUM(E34:J34) -> 10 | M34: M2 | N34: =E34*'ANALISA PINTU JENDELA'!$K$84 -> 0 | O34: =F34*'ANALISA PINTU JENDELA'!$K$84 -> 40.8 | P34: =G34*'ANALISA PINTU JENDELA'!$K$84 -> 81.6 | Q34: =H34*'ANALISA PINTU JENDELA'!$K$84 -> 40.8 | R34: =I34*'ANALISA PINTU JENDELA'!$K$84 -> 40.8 | S34: =J34*'ANALISA PINTU JENDELA'!$K$84 -> 0
C35: JENDELA J4 | D35: UNIT | E35: 0 | F35: 0 | G35: 2 | H35: 0 | I35: 0 | J35: 0 | L35: =SUM(E35:J35) -> 2 | M35: M2 | N35: =E35*'ANALISA PINTU JENDELA'!$K$95 -> 0 | O35: =F35*'ANALISA PINTU JENDELA'!$K$95 -> 0 | P35: =G35*'ANALISA PINTU JENDELA'!$K$95 -> 7.95 | Q35: =H35*'ANALISA PINTU JENDELA'!$K$95 -> 0 | R35: =I35*'ANALISA PINTU JENDELA'!$K$95 -> 0 | S35: =J35*'ANALISA PINTU JENDELA'!$K$95 -> 0
C36: JENDELA J5 | D36: UNIT | E36: 0 | F36: 0 | G36: 1 | H36: 0 | I36: 0 | J36: 0 | L36: =SUM(E36:J36) -> 1 | M36: M2 | N36: =E36*'ANALISA PINTU JENDELA'!$K$105 -> 0 | O36: =F36*'ANALISA PINTU JENDELA'!$K$105 -> 0 | P36: =G36*'ANALISA PINTU JENDELA'!$K$105 -> 7.8175 | Q36: =H36*'ANALISA PINTU JENDELA'!$K$105 -> 0 | R36: =I36*'ANALISA PINTU JENDELA'!$K$105 -> 0 | S36: =J36*'ANALISA PINTU JENDELA'!$K$105 -> 0
C37: JENDELA J6 | D37: UNIT | E37: 0 | F37: 0 | G37: 0 | H37: 0 | I37: 1 | J37: 0 | L37: =SUM(E37:J37) -> 1 | M37: M2 | N37: =E37*'ANALISA PINTU JENDELA'!$K$32 -> 0
C38: LOKET L1 | D38: UNIT | E38: 2 | F38: 0 | G38: 0 | H38: 0 | J38: 0 | L38: =SUM(E38:J38) -> 2 | M38: M2 | N38: =E38*'ANALISA PINTU JENDELA'!K115 -> 2.34
C39: LOKET L2 | D39: UNIT | E39: 1 | F39: 0 | G39: 0 | H39: 0 | J39: 0 | L39: =SUM(E39:J39) -> 1 | M39: M2 | N39: =E39*'ANALISA PINTU JENDELA'!K122 -> 1.75
M40: M2 | N40: =SUM(N20:N39) -> 94.51 | O40: =SUM(O20:O39) -> 225.248 | P40: =SUM(P20:P39) -> 290.0875 | Q40: =SUM(Q20:Q39) -> 206.88 | R40: =SUM(R20:R39) -> 207.12 | S40: =SUM(S20:S39) -> 39.84
B47: 3 | C47: LUASAN RUANG :
C48: BASEMENT | D48: M2 | E48: =53.75*19.6 -> 1053.5
C49: 1. MUSHOLA, KOPERASI, FARMASI | D49: M2 | E49: =(9*7.8)-(4*5.9) -> 46.6 | G49: TOILET B | J49: KL | L49: KD
C50: R. KARYAWAN,TOILET, R POMPA | G50: T1 | H50: 1.65 | I50: 1.45 | J50: =H50*I50 -> 2.3925 | L50: =((H50+I50)*2*2.8)-(1*2.4) -> 14.96 | M50: M2
C51: 2. R. CSSD | D51: M2 | E51: =8.5*5.9 -> 50.15 | G51: T2 | H51: 1.65 | I51: 1.45 | J51: =H51*I51 -> 2.3925 | L51: =((H51+I51)*2*2.8)-(1*2.4) -> 14.96 | M51: M2
C52: 3. GDG STORE | D52: M2 | E52: =2.8*5.8 -> 16.24 | G52: T3 | H52: 1 | I52: 1.85 | J52: =H52*I52 -> 1.85 | L52: =((H52+I52)*2*2.8)-(1*2.4) -> 13.56 | M52: M2
C53: 4. POS JAGA | D53: M2 | E53: =2*3.5 -> 7 | G53: T4 | H53: 1.65 | I53: 2 | J53: =H53*I53 -> 3.3 | L53: =((H53+I53)*2*2.8)-(1*2.4) -> 18.04 | M53: M2
...

Sheet ANALISA PINTU JENDELA
B2: ANALISA
B3: KUSEN PINTU - JENDELA
B6: PINTU P1 | C6: =0.95*2.4 -> 2.28 | D6: M2 | J6: PINTU PJ1 | K6: =3.57*2.4 -> 8.568 | L6: M2
B7: ( DIM. 95x240 ) | D7: UPVC SWING | J7: ( DIM. 357x240 ) | L7: UPVC KACA SWING
B10: KUSEN | C10: =(2.4+2.4)+0.95 -> 5.75 | D10: M' | E10: =AHS!H322 -> 183500 | F10: =C10*E10 -> 1055125 | J10: KUSEN | K10: =(3.57+1+1)+(2.4+2.4+2.25+2.25) -> 14.87 | L10: M' | M10: =AHS!$H$322 -> 183500 | N10: =K10*M10 -> 2728645
B11: DAUN PINTU | C11: =0.85*2.35 -> 1.9975 | D11: M2 | E11: =AHS!H266 -> 1525200 | F11: =C11*E11 -> 3046587 | J11: DAUN PINTU KACA | K11: =(0.75*2.35)*2 -> 3.525 | L11: M2 | M11: ='HRG BAHAN'!E62 -> 600000 | N11: =K11*M11 -> 2115000
B12: ENGSEL 4" | C12: 2 | D12: SET | E12: =AHS!H361 -> 67100 | F12: =C12*E12 -> 134200 | J12: KACA MATI | K12: =(0.9*2.15)*2 -> 3.87 | L12: M2 | M12: ='HRG BAHAN'!E60 -> 226400 | N12: =K12*M12 -> 876168
B13: TARIKAN & KUNCI | C13: 1 | D13: UNIT | E13: =AHS!G394 -> 328497.5 | F13: =C13*E13 -> 328497.5 | J13: FLOOR HINGE | K13: 2 | L13: SET | M13: ='HRG BAHAN'!E15 -> 500000 | N13: =K13*M13 -> 1000000
B14: INSTALL | C14: 1 | D14: LS | E14: 150000 | F14: =C14*E14 -> 150000 | J14: HANDLE | K14: 2 | L14: SET | M14: ='HRG BAHAN'!E30 -> 290800 | N14: =K14*M14 -> 581600
E15: TOTAL | F15: =SUM(F10:F14) -> 4714409.5 | J15: INSTALL | K15: 2 | L15: LS | M15: 200000 | N15: =K15*M15 -> 400000
E16: HARGA | F16: =F15*1.15 -> 5421570.9 | M16: TOTAL | N16: =SUM(N10:N15) -> 7701413
M17: HARGA | N17: =N16*1.15 -> 8856624.9
B19: PINTU P2 | C19: =1*2.4 -> 2.4 | D19: M2 | J19: JENDELA J1 | K19: =1.15*1.6 -> 1.84 | L19: M2
B20: ( DIM. 100x240 ) | D20: UPVC SWING | J20: ( DIM. 1,15x1,6 ) | L20: UPVC SWING
B22: KUSEN | C22: =(2.4+2.4)+1 -> 5.8 | D22: M' | E22: =AHS!$H$322 -> 183500 | F22: =C22*E22 -> 1064300 | J22: KUSEN | K22: =(1.15*2)+(1.6*3) -> 7.1 | L22: M' | M22: =AHS!$H$322 -> 183500 | N22: =K22*M22 -> 1302850
B23: DAUN PINTU | C23: =0.9*2.35 -> 2.115 | D23: M2 | E23: =AHS!$H$266 -> 1525200 | F23: =C23*E23 -> 3225798 | J23: DAUN JENDELA KACA | K23: =2*(0.5*1.5) -> 1.5 | L23: M2 | M23: =AHS!$L$304 -> 1747558.5 | N23: =K23*M23 -> 2621337.8
B24: ENGSEL 4" | C24: 2 | D24: SET | E24: =AHS!$H$361 -> 67100 | F24: =C24*E24 -> 134200 | J24: ENGSEL 3" | K24: 2 | L24: SET | M24: ='HRG BAHAN'!$E$10 -> 18900 | N24: =K24*M24 -> 37800
B25: TARIKAN & KUNCI | C25: 1 | D25: UNIT | E25: =AHS!$G$394 -> 328497.5 | F25: =C25*E25 -> 328497.5 | J25: GERENDEL | K25: 2 | L25: BH | M25: ='HRG BAHAN'!$E$16 -> 32600 | N25: =K25*M25 -> 65200
B26: INSTALL | C26: 1 | D26: LS | E26: 150000 | F26: =C26*E26 -> 150000 | J26: KAIT ANGIN | K26: 2 | L26: SET | M26: ='HRG BAHAN'!$E$21 -> 12000 | N26: =K26*M26 -> 24000
E27: TOTAL | F27: =SUM(F22:F26) -> 4902795.5 | J27: INSTALL | K27: 2 | L27: LS | M27: 125000 | N27: =K27*M27 -> 250000
E28: HARGA | F28: =F27*1.15 -> 5638214.8 | M28: TOTAL | N28: =SUM(N22:N27) -> 4301187.8
M29: HARGA | N29: =N28*1.15 -> 4946366
B32: PINTU P3 | C32: =1.3*2.4 -> 3.12 | D32: M2 | J32: JENDELA J1A | K32: =1.15*1.2 -> 1.38 | L32: M2
B33: ( DIM. 130x240 ) | D33: UPVC DOUBLESWING | J33: ( DIM. 1,15x1,2 ) | L33: UPVC SWING
B35: KUSEN | C35: =(2.4+2.4)+1.3 -> 6.1 | D35: M' | E35: =AHS!$H$322 -> 183500 | F35: =C35*E35 -> 1119350 | J35: KUSEN | K35: =(1.15*2)+(1.2*3) -> 5.9 | L35: M' | M35: =AHS!$H$322 -> 183500 | N35: =K35*M35 -> 1082650
B36: DAUN PINTU | C36: =(0.4*2.35)+(0.8*2.35) -> 2.82 | D36: M2 | E36: =AHS!$H$266 -> 1525200 | F36: =C36*E36 -> 4301064 | J36: DAUN JENDELA KACA | K36: =2*(0.5*1.1) -> 1.1 | L36: M2 | M36: =AHS!$L$304 -> 1747558.5 | N36: =K36*M36 -> 1922314.4
B37: ENGSEL 4" | C37: 3 | D37: SET | E37: =AHS!$H$361 -> 67100 | F37: =C37*E37 -> 201300 | J37: ENGSEL 3" | K37: 2 | L37: SET | M37: ='HRG BAHAN'!$E$10 -> 18900 | N37: =K37*M37 -> 37800
B38: TARIKAN & KUNCI | C38: 1 | D38: UNIT | E38: =AHS!$G$394 -> 328497.5 | F38: =C38*E38 -> 328497.5 | J38: GERENDEL | K38: 2 | L38: BH | M38: ='HRG BAHAN'!$E$16 -> 32600 | N38: =K38*M38 -> 65200
B39: INSTALL | C39: 2 | D39: LS | E39: 150000 | F39: =C39*E39 -> 300000 | J39: KAIT ANGIN | K39: 2 | L39: SET | M39: ='HRG BAHAN'!$E$21 -> 12000 | N39: =K39*M39 -> 24000
E40: TOTAL | F40: =SUM(F35:F39) -> 6250211.5 | J40: INSTALL | K40: 2 | L40: LS | M40: 125000 | N40: =K40*M40 -> 250000
E41: HARGA | F41: =F40*1.15 -> 7187743.2 | M41: TOTAL | N41: =SUM(N35:N40) -> 3381964.4
M42: HARGA | N42: =N41*1.15 -> 3889259
B45: PINTU P3A | C45: =1.7*2.4 -> 4.08 | D45: M2 | J45: JENDELA J2 | K45: =2.15*1.6 -> 3.44 | L45: M2
B46: ( DIM. 170x240 ) | D46: UPVC DOUBLESWING | J46: ( DIM. 2,15x1,6 ) | L46: UPVC SWING
B48: KUSEN | C48: =(2.4+2.4)+1.7 -> 6.5 | D48: M' | E48: =AHS!$H$322 -> 183500 | F48: =C48*E48 -> 1192750 | J48: KUSEN | K48: =(2.15*2)+(1.6*4) -> 10.7 | L48: M' | M48: =AHS!$H$322 -> 183500 | N48: =K48*M48 -> 1963450
B49: DAUN PINTU | C49: =2*(0.8*2.35) -> 3.76 | D49: M2 | E49: =AHS!$H$266 -> 1525200 | F49: =C49*E49 -> 5734752 | J49: DAUN JENDELA KACA | K49: =2*(0.5*1.5) -> 1.5 | L49: M2 | M49: =AHS!$L$304 -> 1747558.5 | N49: =K49*M49 -> 2621337.8
B50: ENGSEL 4" | C50: 3 | D50: SET | E50: =AHS!$H$361 -> 67100 | F50: =C50*E50 -> 201300 | J50: KACA MATI | K50: =(0.9*1.5) -> 1.35 | L50: M2 | M50: ='HRG BAHAN'!E59 -> 237000 | N50: =K50*M50 -> 319950
B51: TARIKAN & KUNCI | C51: 1 | D51: UNIT | E51: =AHS!$G$394 -> 328497.5 | F51: =C51*E51 -> 328497.5 | J51: ENGSEL 3" | K51: 2 | L51: SET | M51: ='HRG BAHAN'!$E$10 -> 18900 | N51: =K51*M51 -> 37800
B52: INSTALL | C52: 2 | D52: LS | E52: 150000 | F52: =C52*E52 -> 300000 | J52: GERENDEL | K52: 2 | L52: BH | M52: ='HRG BAHAN'!$E$16 -> 32600 | N52: =K52*M52 -> 65200
E53: TOTAL | F53: =SUM(F48:F52) -> 7757299.5 | J53: KAIT ANGIN | K53: 2 | L53: SET | M53: ='HRG BAHAN'!$E$21 -> 12000 | N53: =K53*M53 -> 24000
...

Sheet HRG BAHAN
A2: I | B2: MATERIAL KUNCI DAN ENGSEL
A3: 1 | C3: 1 set kunci pintu (kw 1) | D3: buah | E3: 180900
A4: 2 | C4: 1 set kunci pintu (kw 2) | D4: buah | E4: 117900
A5: 3 | C5: 1 set handle+kunci | D5: buah | E5: 279000
A6: 4 | C6: Door closer | D6: buah | E6: 167500
A7: 5 | C7: Door holder | D7: buah | E7: 81000
A8: 6 | C8: Door stop | D8: buah | E8: 58500
A9: 7 | C9: Engsel angin | D9: buah | E9: 27400
A10: 8 | C10: Engsel jendela | D10: buah | E10: 18900
A11: 9 | C11: Engsel kupu-kupu | D11: buah | E11: 41700
A12: 10 | C12: Engsel lengan jendela | D12: buah | E12: 26500
A13: 11 | C13: Engsel pintu (kw 1) | D13: buah | E13: 31500
A14: 12 | C14: Engsel pintu (kw 2) | D14: buah | E14: 23700
... A35: 33 | C35: Venetions blinds dan vertical blinds | D35: m2 | E35: 140000
A37: J | B37: MATERIAL KACA
A38: 1 | C38: Glass block 20x20 cm | D38: buah | E38: 2500
A39: 2 | C39: Frame besi kaca nako | D39: daun | E39: 400000
A40: 3 | C40: Jendela nako | D40: buah | E40: 400000
A41: 4 | C41: Jendela Kaca Upvc 2 daun | D41: buah | E41: 2000000
A42: 5 | C42: Jendela Ornamen GRC | D42: buah | E42: 596000
A43: 6 | C43: Jendela Nako Rangka Aluminium (rangka+kaca 5 mm) | D43: m2 | E43: 242000
A44: 7 | C44: Kaca buram 12mm | D44: m2 | E44: 317000
A45: 8 | C45: Kaca cermin 5 mm | D45: m2 | E45: 221400
A46: 9 | C46: Kaca cermin 6mm | D46: m2 | E46: 270900
A47: 10 | C47: Kaca cermin 8 mm | D47: m2 | E47: 796100
A48: 11 | C48: Kaca es kabur 3 mm | D48: m2 | E48: 85000
A49: 12 | C49: Kaca es kabur 5 mm | D49: m2 | E49: 95000
... A69: 32 | C69: Ray Band 5mm | D69: m2 | E69: 112400

Sheet AHS
B5: 3.6.1.9 | C5: Pemasangan 1 m2 dinding bata merah tebal 1/2 batu dengan mortar tipe O,fc’ 2,4 MPa (Setara Campuran 1SP : 5PP) | H5: =ROUNDDOWN(G22,-2) -> 129000 | K5: 3.6.4.2 | L5: Pemasangan 1 m2 dinding bata ringan tebal 10 cm dengan mortar siap pakai | Q5: =ROUNDDOWN(P21,-2) -> 153400
B6: No | C6: Uraian | D6: Sat. | E6: Koefisien | F6: Harga Satuan (Rp) | G6: Jumlah Harga (Rp) | K6: No | L6: Uraian | M6: Sat. | N6: Koefisien | O6: Harga Satuan (Rp) | P6: Jumlah Harga (Rp)
B7: A | C7: TENAGA KERJA | K7: A | L7: TENAGA KERJA
B8: 1 | C8: Pekerja | D8: OH | E8: 0.2 | F8: 100000 | G8: =E8*F8 -> 20000 | K8: 1 | L8: Pekerja | M8: OH | N8: 0.1677 | O8: 100000 | P8: =N8*O8 -> 16770
B9: 2 | C9: Tukang batu | D9: OH | E9: 0.1 | F9: 145000 | G9: =E9*F9 -> 14500 | K9: 2 | L9: Tukang batu | M9: OH | N9: 0.0833 | O9: 145000 | P9: =N9*O9 -> 12078.5
B10: 3 | C10: Kepala tukang | D10: OH | E10: 0.01 | F10: 175000 | G10: =E10*F10 -> 1750 | K10: 3 | L10: Kepala tukang | M10: OH | N10: 0.0083 | O10: 175000 | P10: =N10*O10 -> 1452.5
B11: 4 | C11: Mandor | D11: OH | E11: 0.0033 | F11: 200000 | G11: =E11*F11 -> 660 | K11: 4 | L11: Mandor | M11: OH | N11: 0.0028 | O11: 200000 | P11: =N11*O11 -> 560
B12: JUMLAH TENAGA KERJA | G12: =SUM(G8:G11) -> 36910 | K12: JUMLAH TENAGA KERJA | P12: =SUM(P8:P11) -> 30861
B13: B | C13: BAHAN | K13: B | L13: BAHAN
B14: 1 | C14: Bata merah | D14: buah | E14: 71.91 | F14: 700 | G14: =E14*F14 -> 50337 | K14: 1 | L14: Bata ringan tebal 10 cm | M14: buah | N14: 8.75 | O14: 11000 | P14: =N14*O14 -> 96250
B15: 2 | C15: Semen portland (PC) | D15: kg | E15: 9.68 | F15: 1300 | G15: =E15*F15 -> 12584 | K15: 2 | L15: Mortar siap pakai | M15: kg | N15: 3.429 | O15: 1850 | P15: =N15*O15 -> 6343.65
B16: 3 | C16: Pasir pasang (quarry - lokasi pekerjaan) | D16: m3 | E16: 0.045 | F16: 275000 | G16: =E16*F16 -> 12375 | K16: JUMLAH HARGA BAHAN | P16: =SUM(P14:P15) -> 102593.65
B17: JUMLAH HARGA BAHAN | G17: =SUM(G14:G16) -> 75296 | K17: C | L17: PERALATAN
B18: C | C18: PERALATAN | K18: JUMLAH HARGA ALAT | P18: 0
B19: JUMLAH HARGA ALAT | G19: 0 | K19: D | L19: Jumlah (A+B+C) | P19: =P16+P12 -> 133454.65
B20: D | C20: Jumlah (A+B+C) | G20: =G12+G17+G19 -> 112206 | K20: E | L20: Biaya Umum dan Keuntungan 10% - 15% x D | O20: 0.1 | P20: =P19*0.15 -> 20018.197
B21: E | C21: Biaya Umum dan Keuntungan 10% - 15% x D | F21: 0.1 | G21: =G20*0.15 -> 16830.9 | K21: F | L21: Harga Satuan Pekerjaan (D+E) | P21: =P19+P20 -> 153472.85
B22: F | C22: Harga Satuan Pekerjaan (D+E) | G22: =G20+G21 -> 129036.9
B28: 3.6.2.3 | C28: Pemasangan 1 m2 dinding conblock HB15 dengan mortar tipe S,fc’ 12,5 MPa (Setara Campuran 1SP : 3PP) | H28: =ROUNDDOWN(G46,-2) -> 427000 | K28: 3.6.6.1 | L28: Pemasangan 1 m2 dinding partisi, Gypsumboard t=9mm | Q28: =ROUNDDOWN(P46,-2) -> 104000
B29: No | C29: Uraian | D29: Sat. | E29: Koefisien | F29: Harga Satuan (Rp) | G29: Jumlah Harga (Rp) | K29: No | L29: Uraian | M29: Sat. | N29: Koefisien | O29: Harga Satuan (Rp) | P29: Jumlah Harga (Rp)
B30: A | C30: TENAGA KERJA | K30: A | L30: TENAGA KERJA
B31: 1 | C31: Pekerja | D31: OH | E31: 0.1667 | F31: 100000 | G31: =E31*F31 -> 16670 | K31: 1 | L31: Pekerja | M31: OH | N31: 0.2 | O31: 100000 | P31: =N31*O31 -> 20000
B32: 2 | C32: Tukang batu | D32: OH | E32: 0.0833 | F32: 145000 | G32: =E32*F32 -> 12078.5 | K32: 2 | L32: Tukang batu | M32: OH | N32: 0.1 | O32: 145000 | P32: =N32*O32 -> 14500
B33: 3 | C33: Kepala tukang | D33: OH | E33: 0.0083 | F33: 175000 | G33: =E33*F33 -> 1452.5 | K33: 3 | L33: Kepala tukang | M33: OH | N33: 0.01 | O33: 175000 | P33: =N33*O33 -> 1750
B34: 4 | C34: Mandor | D34: OH | E34: 0.0028 | F34: 200000 | G34: =E34*F34 -> 560 | K34: 4 | L34: Mandor | M34: OH | N34: 0.003 | O34: 200000 | P34: =N34*O34 -> 600
B35: JUMLAH TENAGA KERJA | G35: =SUM(G31:G34) -> 30761 | K35: JUMLAH TENAGA KERJA | P35: =SUM(P31:P34) -> 36850
B36: B | C36: BAHAN | K36: B | L36: BAHAN
B37: 1 | C37: HB-15 | D37: buah | E37: 12.5 | F37: 12000 | G37: =E37*F37 -> 150000 | K37: 1 | L37: Gypsum Board (122 cm x 244 cm x 9 mm) | M37: buah | N37: 0.739 | O37: 70000 | P37: =N37*O37 -> 51730
B38: 2 | C38: Semen portland (PC) | D38: kg | E38: 22.74 | F38: 1300 | G38: =E38*F38 -> 29562 | K38: 2 | L38: Rockwool tebal 50 mm | M38: kg | N38: 0 | O38: 290000 | P38: =N38*O38 -> 0
B39: 3 | C39: Pasir pasang (quarry - lokasi pekerjaan) | D39: m3 | E39: 0.55 | F39: 275000 | G39: =E39*F39 -> 151250 | K39: 3 | L39: Paku sekrup | M39: m3 | N39: 0.05 | O39: 30090 | P39: =N39*O39 -> 1504.5
B40: 4 | C40: Besi angkur diameter 8 | D40: kg | E40: 0.28 | F40: 35000 | G40: =E40*F40 -> 9800 | K40: 4 | L40: Compound gypsum | M40: kg | N40: 0.106 | O40: 3500 | P40: =N40*O40 -> 371
B41: JUMLAH HARGA BAHAN | G41: =SUM(G37:G40) -> 340612 | K41: JUMLAH HARGA BAHAN | P41: =SUM(P37:P40) -> 53605.5
B42: C | C42: PERALATAN | K42: C | L42: PERALATAN
B43: JUMLAH HARGA ALAT | G43: 0 | K43: JUMLAH HARGA ALAT | P43: 0
B44: D | C44: Jumlah (A+B+C) | G44: =G35+G41+G43 -> 371373 | K44: D | L44: Jumlah (A+B+C) | P44: =P41+P35 -> 90455.5
B45: E | C45: Biaya Umum dan Keuntungan 10% - 15% x D | F45: 0.1 | G45: =G44*0.15 -> 55705.95 | K45: E | L45: Biaya Umum dan Keuntungan 10% - 15% x D | O45: 0.1 | P45: =P44*0.15 -> 13568.325
B46: F | C46: Harga Satuan Pekerjaan (D+E) | G46: =G44+G45 -> 427078.95 | K46: F | L46: Harga Satuan Pekerjaan (D+E) | P46: =SUM(P43:P45) -> 104023.82
B50: 3.7.2 | C50: Pemasangan 1 m2 plesteran 1SP : 2PP tebal 15 mm | H50: =ROUNDDOWN(G66,-2) -> 64000
B51: No | C51: Uraian | D51: Sat. | E51: Koefisien | F51: Harga Satuan (Rp) | G51: Jumlah Harga (Rp)
B52: A | C52: TENAGA KERJA
...

Sheet RAB
B2: RENCANA ANGGARAN BIAYA
B3: RSU SARI DHARMA
B4: JL. PULAU SERAM NO. 1
B5: DENPASAR
C7: PEKERJAAN ARSITEKTUR
B10: NO | C10: ITEM PEKERJAAN | D10: KETERANGAN | E10: VOL. | F10: SAT. | G10: HRG. SAT. | H10: HRG. TOTAL
B11: 1 | C11: 2 | D11: 3 | E11: 4 | F11: 5 | G11: 6 | H11: 7
B13: I | C13: LANTAI BASEMENT
B15: I.1 | C15: PEK. PAS. DINDING
B16: 1 | C16: PAS. DINDING BT RINGAN | E16: ='ANALISA VOLUME'!E16-'ANALISA VOLUME'!N40 -> 1283.25 | F16: M2 | G16: =AHS!$Q$5 -> 153400 | H16: =E16*G16 -> 1.9685055e+08
C17: 1. PAS. BATA RINGAN | D17: EX. CITICON | G17: =AHS!$Q$5 -> 153400
C18: 2. PARTISI GIPSUM TANPA ROCKWOOL | D18: EX. JAYA 9mm | G18: =AHS!$Q$28+AHS!$Q$172 -> 243700
B19: 2 | C19: PEK. PLESTER ACI | E19: =E16*2 -> 2566.5 | F19: M2 | G19: =AHS!$H$50+AHS!$H$69 -> 111300 | H19: =E19*G19 -> 2.8565145e+08
B21: I.2 | C21: PEK. PLAFOND
B22: 1 | C22: PAS. GIPSUM | D22: EX.JAYA | E22: ='ANALISA VOLUME'!E48 -> 1053.5 | F22: M2 | G22: =AHS!$Q$172+AHS!$H$172 -> 194000 | H22: =E22*G22 -> 204379000
B23: 2 | C23: PAS. SHADOWLINE | D23: EX. KENCANA | E23: =('ANALISA VOLUME'!E13+'ANALISA VOLUME'!E14)*2 -> 861.1 | F23: M' | G23: 35000 | H23: =E23*G23 -> 30138500
B25: I.3 | C25: PEK. PENUTUP LANTAI & DINDING
B26: 1 | C26: PAS. KERAMIK LANTAI | E26: ='ANALISA VOLUME'!E62 -> 355.92 | F26: M2
C27: 1. KM/WC, CUCI | D27: EX. ROMAN | E27: ='ANALISA VOLUME'!J59 -> 30.3375 | F27: M2 | G27: =AHS!$H$87 -> 222000 | H27: =E27*G27 -> 6734925
C28: 2. RUANGAN | D28: EX. ROMAN | E28: =E26-E27 -> 325.5825 | F28: M2 | G28: =AHS!$H$109 -> 354000 | H28: =E28*G28 -> 1.1525621e+08
B29: 2 | C29: PAS. PLINT KERAMIK | D29: EX. ROMAN | E29: =E23 -> 861.1 | F29: M' | G29: =AHS!$H$130 -> 40400 | H29: =E29*G29 -> 34788440
B30: 3 | C30: PAS. KERAMIK DINDING TOILET | D30: EX. ROMAN | E30: ='ANALISA VOLUME'!L71 -> 1.65 | F30: M2 | G30: =AHS!$H$151 -> 269900 | H30: =E30*G30 -> 445335
B32: I.4 | C32: PEK. KUSEN PINTU JENDELA | D32: UPVC MIX
B33: 1 | C33: PINTU P1 | E33: 5 | F33: UNIT | G33: ='ANALISA PINTU JENDELA'!F16 -> 5421570.9 | H33: =E33*G33 -> 27107855
B34: 2 | C34: PINTU P1 KM | E34: 5 | F34: UNIT | G34: ='ANALISA PINTU JENDELA'!F16 -> 5421570.9 | H34: =E34*G34 -> 27107855
B35: 3 | C35: PINTU P2 | E35: 13 | F35: UNIT | G35: ='ANALISA PINTU JENDELA'!F28 -> 5638214.8 | H35: =E35*G35 -> 73296793
B36: 4 | C36: PINTU P3 | E36: 4 | F36: UNIT | G36: ='ANALISA PINTU JENDELA'!F41 -> 7187743.2 | H36: =E36*G36 -> 28750973
B37: 5 | C37: PINTU P7 | E37: 2 | F37: UNIT | G37: ='ANALISA PINTU JENDELA'!F120 -> 6153646 | H37: =E37*G37 -> 12307292
B38: 6 | C38: JENDELA J1A | E38: 12 | F38: UNIT | G38: ='ANALISA PINTU JENDELA'!N42 -> 3889259 | H38: =E38*G38 -> 46671108
B39: 7 | C39: JENDELA J2A | E39: 1 | F39: UNIT | G39: ='ANALISA PINTU JENDELA'!N70 -> 2914036 | H39: =E39*G39 -> 2914036
B40: 8 | C40: LOKET L1 | E40: 2 | F40: UNIT | G40: ='ANALISA PINTU JENDELA'!N121 -> 1210599.2 | H40: =E40*G40 -> 2421198.5
B41: 9 | C41: LOKET L2 | E41: 1 | F41: UNIT | G41: ='ANALISA PINTU JENDELA'!N128 -> 3430656.1 | H41: =E41*G41 -> 3430656.1
B44: I.5 | C44: PEK. MEP
B45: 1 | C45: PEK. AMATEUR SANITAIR
C46: 1. PAS. CLOSET DUDUK | D46: EX. TOTO | E46: 6 | F46: UNIT | G46: =AHS!$H$415 -> 2107200 | H46: =E46*G46 -> 12643200
C47: 2. PAS. SHOWER | D47: EX. TOTO | E47: 5 | F47: SET | G47: =AHS!$H$434 -> 845000 | H47: =E47*G47 -> 4225000
C48: 3. PAS. WASHTAFEL | D48: EX. TOTO | E48: 6 | F48: UNIT | G48: =AHS!$H$508 -> 673000 | H48: =E48*G48 -> 4038000
C49: 4. PAS. FLOOR DRAIN | E49: 10 | F49: BH | G49: =AHS!$H$490 -> 72000 | H49: =E49*G49 -> 720000
C50: 5. PAS. KRAN MEJA | E50: 6 | F50: SET | G50: =AHS!$H$453 -> 127000 | H50: =E50*G50 -> 762000
C51: 6. PAS. JET WASHER | D51: EX. TOTO | E51: 6 | F51: UNIT | G51: =AHS!$H$471 -> 194100 | H51: =E51*G51 -> 1164600
...
